Workbook

Sheet Solar Power Plant Data
A1: Date Hour (NMT) | B1: Wind Speed | C1: Sunshine | D1: Air Pressure | E1: Radiation | F1: Air Temperature | G1: Relative Air Humidity | H1: System Production
A2: 42736 | B2: 0,6 | C2: 0 | D2: 1003,8 | E2: 0 | F2: 0,1 | G2: 97 | H2: 0 | J2: Missing Value | K2: =COUNTBLANK(B2:H745) -> 0
A3: 42736.042 | B3: 1,7 | C3: 0 | D3: 1003,5 | E3: 0 | F3: -0,2 | G3: 98 | H3: 0
A4: 42736.083 | B4: 0,6 | C4: 0 | D4: 1003,4 | E4: 0 | F4: -1,2 | G4: 99 | H4: 0 | K4: Wind Speed | L4: Sunshine | M4: Air Pressure | N4: Radiation | O4: Air Temperature | P4: Relative Air Humidity | Q4: System Production
A5: 42736.125 | B5: 2,4 | C5: 0 | D5: 1003,3 | E5: 0 | F5: -1,3 | G5: 99 | H5: 0 | J5: Rata Rata | K5: =AVERAGE(B2:B745) -> 1.9180328 | L5: =AVERAGE(C2:C745) -> 3.8870968 | M5: =AVERAGE(D2:D745) -> 1017.7143 | N5: =AVERAGE(E2:E745) -> 1.9493007 | O5: =AVERAGE(F2:F745) -> -2.07 | P5: =AVERAGE(G2:G745) -> 86.919355 | Q5: =AVERAGE(H2:H745) -> 515351.97
A6: 42736.167 | B6: 4 | C6: 0 | D6: 1003,1 | E6: 0 | F6: 3,6 | G6: 67 | H6: 0 | J6: Median | K6: =MEDIAN(B2:B745) -> 1 | L6: =MEDIAN(C2:C745) -> 0 | M6: =MEDIAN(D2:D745) -> 1023 | N6: =MEDIAN(E2:E745) -> 0 | O6: =MEDIAN(F2:F745) -> -2 | P6: =MEDIAN(G2:G745) -> 91 | Q6: =MEDIAN(H2:H745) -> 0
A7: 42736.208 | B7: 1,4 | C7: 0 | D7: 1003,1 | E7: 0 | F7: 1,5 | G7: 74 | H7: 0 | J7: Standar Deviasi | K7: =STDEV(B2:B745) -> 1.2687932 | L7: =STDEV(C2:C745) -> 13.394748 | M7: =STDEV(D2:D745) -> 16.391804 | N7: =STDEV(E2:E745) -> 11.659015 | O7: =STDEV(F2:F745) -> 3.0558935 | P7: =STDEV(G2:G745) -> 12.530725 | Q7: =STDEV(H2:H745) -> 1929899.3
A8: 42736.25 | B8: 1,4 | C8: 0 | D8: 1003,7 | E8: 0 | F8: 0,4 | G8: 79 | H8: 0
A9: 42736.292 | B9: 1,3 | C9: 0 | D9: 1003,9 | E9: 0 | F9: -0,9 | G9: 81 | H9: 0
A10: 42736.333 | B10: 0,6 | C10: 0 | D10: 1004,3 | E10: 0 | F10: -1 | G10: 77 | H10: 0 | J10: Korelasi | K10: Wind Speed | L10: Sunshine | M10: Air Pressure | N10: Radiation | O10: Air Temperature | P10: Relative Air Humidity | Q10: System Production
A11: 42736.375 | B11: 0,6 | C11: 0 | D11: 1004,8 | E11: 0 | F11: -2 | G11: 81 | H11: 0 | J11: Wind Speed | K11: 1 | L11: =CORREL(B2:B745,C2:C745) -> -0.067871243 | M11: =CORREL(B2:B745,D2:D745) -> -0.98932278 | N11: =CORREL(B2:B745,E2:E745) -> 0.14059878 | O11: =CORREL(B2:B745,F2:F745) -> 0.33468531 | P11: =CORREL(B2:B745,G2:G745) -> -0.23446783 | Q11: =CORREL(B2:B745,H2:H745) -> -0.18945335
A12: 42736.417 | B12: 0,4 | C12: 0 | D12: 1005,2 | E12: 0 | F12: -1,9 | G12: 80 | H12: 0 | J12: Sunshine | K12: =CORREL(B2:B745,C2:C745) -> -0.067871243 | L12: 1 | M12: =CORREL(C2:C745,D2:D745) -> -0.10111956 | N12: =CORREL(C2:C745,E2:E745) -> 0.7496455 | O12: =CORREL(C2:C745,F2:F745) -> 0.16858742 | P12: =CORREL(C2:C745,G2:G745) -> -0.36892758 | Q12: =CORREL(C2:C745,H2:H745) -> 0.36169091
A13: 42736.458 | B13: 1,1 | C13: 46 | D13: 1005,8 | E13: 49,7 | F13: -0,2 | G13: 74 | H13: 2158333 | J13: Air Pressure | K13: =CORREL(B2:B745,D2:D745) -> -0.98932278 | L13: =CORREL(C2:C745,D2:D745) -> -0.10111956 | M13: 1 | N13: =CORREL(D2:D745,E2:E745) -> 0.019740792 | O13: =CORREL(D2:D745,F2:F745) -> -0.47782225 | P13: =CORREL(D2:D745,G2:G745) -> 0.14693448 | Q13: =CORREL(D2:D745,H2:H745) -> 0.10040959
A14: 42736.5 | B14: 1,2 | C14: 60 | D14: 1006,1 | E14: 138,7 | F14: 1,8 | G14: 72 | H14: 8316667 | J14: Radiation | K14: =CORREL(B2:B745,E2:E745) -> 0.14059878 | L14: =CORREL(C2:C745,E2:E745) -> 0.7496455 | M14: =CORREL(D2:D745,E2:E745) -> 0.019740792 | N14: 1 | O14: =CORREL(E2:E745,F2:F745) -> 0.25444002 | P14: =CORREL(E2:E745,G2:G745) -> -0.18899918 | Q14: =CORREL(E2:E745,H2:H745) -> 0.58869385
A15: 42736.542 | B15: 0,4 | C15: 59 | D15: 1006,1 | E15: 121,6 | F15: 2,7 | G15: 66 | H15: 349.5 | J15: Air Temperature | K15: =CORREL(B2:B745,F2:F745) -> 0.33468531 | L15: =CORREL(C2:C745,F2:F745) -> 0.16858742 | M15: =CORREL(D2:D745,F2:F745) -> -0.47782225 | N15: =CORREL(E2:E745,F2:F745) -> 0.25444002 | O15: 1 | P15: =CORREL(F2:F745,G2:G745) -> 0.13136485 | Q15: =CORREL(F2:F745,H2:H745) -> 0.054503562
A16: 42736.583 | B16: 4 | C16: 55 | D16: 1006,5 | E16: 77 | F16: 5 | G16: 49 | H16: 272 | J16: Relative Air Humidity | K16: =CORREL(B2:B745,G2:G745) -> -0.23446783 | L16: =CORREL(C2:C745,G2:G745) -> -0.36892758 | M16: =CORREL(D2:D745,G2:G745) -> 0.14693448 | N16: =CORREL(E2:E745,G2:G745) -> -0.18899918 | O16: =CORREL(F2:F745,G2:G745) -> 0.13136485 | P16: 1 | Q16: =CORREL(G2:G745,H2:H745) -> -0.050113854
A17: 42736.625 | B17: 2,7 | C17: 26 | D17: 1007,6 | E17: 33,1 | F17: 4,8 | G17: 48 | H17: 1302083 | J17: System Production | K17: =CORREL(B2:B745,H2:H745) -> -0.18945335 | L17: =CORREL(C2:C745,H2:H745) -> 0.36169091 | M17: =CORREL(D2:D745,H2:H745) -> 0.10040959 | N17: =CORREL(E2:E745,H2:H745) -> 0.58869385 | O17: =CORREL(F2:F745,H2:H745) -> 0.054503562 | P17: =CORREL(G2:G745,H2:H745) -> -0.050113854 | Q17: 1
A18: 42736.667 | B18: 2,5 | C18: 16 | D18: 1008,5 | E18: 0 | F18: 3,8 | G18: 49 | H18: 0
A19: 42736.708 | B19: 3,8 | C19: 0 | D19: 1009,1 | E19: 0 | F19: 3,2 | G19: 50 | H19: 0
A20: 42736.75 | B20: 4,7 | C20: 0 | D20: 1010 | E20: 0 | F20: 3,2 | G20: 48 | H20: 0
A21: 42736.792 | B21: 4,2 | C21: 0 | D21: 1011,2 | E21: 0 | F21: 2,8 | G21: 48 | H21: 0
A22: 42736.833 | B22: 4,8 | C22: 0 | D22: 1012,2 | E22: 0 | F22: 2,3 | G22: 47 | H22: 0
A23: 42736.875 | B23: 3,3 | C23: 0 | D23: 1012,7 | E23: 0 | F23: 1,5 | G23: 48 | H23: 0
A24: 42736.917 | B24: 4 | C24: 0 | D24: 1013,1 | E24: 0 | F24: 1,1 | G24: 47 | H24: 0
A25: 42736.958 | B25: 2,6 | C25: 0 | D25: 1013,4 | E25: 0 | F25: 0,5 | G25: 48 | H25: 0
A26: 42767 | B26: 1,2 | C26: 0 | D26: 1013,6 | E26: 0 | F26: -2,1 | G26: 61 | H26: 0
A27: 42767.042 | B27: 1,1 | C27: 0 | D27: 1013,3 | E27: 0 | F27: -3 | G27: 65 | H27: 0
A28: 42767.083 | B28: 1 | C28: 0 | D28: 1013,3 | E28: 0 | F28: -3,1 | G28: 66 | H28: 0
A29: 42767.125 | B29: 0,7 | C29: 0 | D29: 1013,4 | E29: 0 | F29: -3,4 | G29: 66 | H29: 0
A30: 42767.167 | B30: 1,4 | C30: 0 | D30: 1013,2 | E30: 0 | F30: -3,4 | G30: 62 | H30: 0
A31: 42767.208 | B31: 0,6 | C31: 0 | D31: 1013,2 | E31: 0 | F31: -3,4 | G31: 65 | H31: 0
A32: 42767.25 | B32: 1,5 | C32: 0 | D32: 1012,8 | E32: 0 | F32: -2 | G32: 58 | H32: 0
A33: 42767.292 | B33: 1,1 | C33: 0 | D33: 1012,5 | E33: 0 | F33: -3 | G33: 64 | H33: 0
A34: 42767.333 | B34: 0,4 | C34: 0 | D34: 1012,2 | E34: 0 | F34: -3,3 | G34: 67 | H34: 0
A35: 42767.375 | B35: 1,3 | C35: 0 | D35: 1012,2 | E35: 0 | F35: -3 | G35: 67 | H35: 0
A36: 42767.417 | B36: 0,4 | C36: 7 | D36: 1012,3 | E36: 6,4 | F36: -3 | G36: 68 | H36: 0
A37: 42767.458 | B37: 1 | C37: 9 | D37: 1012,3 | E37: 40,1 | F37: -2,3 | G37: 67 | H37: 2486667
A38: 42767.5 | B38: 1 | C38: 60 | D38: 1012,1 | E38: 71,3 | F38: -1 | G38: 59 | H38: 10873334
A39: 42767.542 | B39: 1,5 | C39: 60 | D39: 1011,9 | E39: 97,5 | F39: 0,6 | G39: 52 | H39: 723
A40: 42767.583 | B40: 1,1 | C40: 60 | D40: 1011,7 | E40: 80 | F40: 0,2 | G40: 51 | H40: 131
...

Sheet Feature Engineering
A2: Hour | B2: Day | C2: Month | D2: Day of Week | E2: Weekend | F2: Lag_24h | G2: Rolling_24h | H2: Eff_Index
A3: =HOUR('Solar Power Plant Data'!A2) -> 0 | B3: =DAY('Solar Power Plant Data'!A2) -> 1 | C3: =MONTH('Solar Power Plant Data'!A2) -> 1 | D3: =TEXT('Solar Power Plant Data'!A2,"ddd") -> Sun | E3: =IF(OR(D3="Sat",D3="Sun"),1,0) -> 1 | F3: {=IF(ROW()<25,"",INDEX('Solar Power Plant Data'!H:H,ROW()-1))} | G3: =IF(ROW()<25,"",AVERAGE(OFFSET('Solar Power Plant Data'!H25,-23,0,24,1))) | H3: ='Solar Power Plant Data'!H2/MAX('Solar Power Plant Data'!E2,0.0001) -> 0
A4: =HOUR('Solar Power Plant Data'!A3) -> 1 | B4: =DAY('Solar Power Plant Data'!A3) -> 1 | C4: =MONTH('Solar Power Plant Data'!A3) -> 1 | D4: =TEXT('Solar Power Plant Data'!A3,"ddd") -> Sun | E4: =IF(OR(D4="Sat",D4="Sun"),1,0) -> 1 | F4: {=IF(ROW()<25,"",INDEX('Solar Power Plant Data'!H:H,ROW()-1))} | G4: =IF(ROW()<25,"",AVERAGE(OFFSET('Solar Power Plant Data'!H26,-23,0,24,1))) | H4: ='Solar Power Plant Data'!H3/MAX('Solar Power Plant Data'!E3,0.0001) -> 0
A5: =HOUR('Solar Power Plant Data'!A4) -> 2 | B5: =DAY('Solar Power Plant Data'!A4) -> 1 | C5: =MONTH('Solar Power Plant Data'!A4) -> 1 | D5: =TEXT('Solar Power Plant Data'!A4,"ddd") -> Sun | E5: =IF(OR(D5="Sat",D5="Sun"),1,0) -> 1 | F5: {=IF(ROW()<25,"",INDEX('Solar Power Plant Data'!H:H,ROW()-1))} | G5: =IF(ROW()<25,"",AVERAGE(OFFSET('Solar Power Plant Data'!H27,-23,0,24,1))) | H5: ='Solar Power Plant Data'!H4/MAX('Solar Power Plant Data'!E4,0.0001) -> 0
A6: =HOUR('Solar Power Plant Data'!A5) -> 3 | B6: =DAY('Solar Power Plant Data'!A5) -> 1 | C6: =MONTH('Solar Power Plant Data'!A5) -> 1 | D6: =TEXT('Solar Power Plant Data'!A5,"ddd") -> Sun | E6: =IF(OR(D6="Sat",D6="Sun"),1,0) -> 1 | F6: {=IF(ROW()<25,"",INDEX('Solar Power Plant Data'!H:H,ROW()-1))} | G6: =IF(ROW()<25,"",AVERAGE(OFFSET('Solar Power Plant Data'!H28,-23,0,24,1))) | H6: ='Solar Power Plant Data'!H5/MAX('Solar Power Plant Data'!E5,0.0001) -> 0
A7: =HOUR('Solar Power Plant Data'!A6) -> 4 | B7: =DAY('Solar Power Plant Data'!A6) -> 1 | C7: =MONTH('Solar Power Plant Data'!A6) -> 1 | D7: =TEXT('Solar Power Plant Data'!A6,"ddd") -> Sun | E7: =IF(OR(D7="Sat",D7="Sun"),1,0) -> 1 | F7: {=IF(ROW()<25,"",INDEX('Solar Power Plant Data'!H:H,ROW()-1))} | G7: =IF(ROW()<25,"",AVERAGE(OFFSET('Solar Power Plant Data'!H29,-23,0,24,1))) | H7: ='Solar Power Plant Data'!H6/MAX('Solar Power Plant Data'!E6,0.0001) -> 0
A8: =HOUR('Solar Power Plant Data'!A7) -> 5 | B8: =DAY('Solar Power Plant Data'!A7) -> 1 | C8: =MONTH('Solar Power Plant Data'!A7) -> 1 | D8: =TEXT('Solar Power Plant Data'!A7,"ddd") -> Sun | E8: =IF(OR(D8="Sat",D8="Sun"),1,0) -> 1 | F8: {=IF(ROW()<25,"",INDEX('Solar Power Plant Data'!H:H,ROW()-1))} | G8: =IF(ROW()<25,"",AVERAGE(OFFSET('Solar Power Plant Data'!H30,-23,0,24,1))) | H8: ='Solar Power Plant Data'!H7/MAX('Solar Power Plant Data'!E7,0.0001) -> 0
A9: =HOUR('Solar Power Plant Data'!A8) -> 6 | B9: =DAY('Solar Power Plant Data'!A8) -> 1 | C9: =MONTH('Solar Power Plant Data'!A8) -> 1 | D9: =TEXT('Solar Power Plant Data'!A8,"ddd") -> Sun | E9: =IF(OR(D9="Sat",D9="Sun"),1,0) -> 1 | F9: {=IF(ROW()<25,"",INDEX('Solar Power Plant Data'!H:H,ROW()-1))} | G9: =IF(ROW()<25,"",AVERAGE(OFFSET('Solar Power Plant Data'!H31,-23,0,24,1))) | H9: ='Solar Power Plant Data'!H8/MAX('Solar Power Plant Data'!E8,0.0001) -> 0
A10: =HOUR('Solar Power Plant Data'!A9) -> 7 | B10: =DAY('Solar Power Plant Data'!A9) -> 1 | C10: =MONTH('Solar Power Plant Data'!A9) -> 1 | D10: =TEXT('Solar Power Plant Data'!A9,"ddd") -> Sun | E10: =IF(OR(D10="Sat",D10="Sun"),1,0) -> 1 | F10: {=IF(ROW()<25,"",INDEX('Solar Power Plant Data'!H:H,ROW()-1))} | G10: =IF(ROW()<25,"",AVERAGE(OFFSET('Solar Power Plant Data'!H32,-23,0,24,1))) | H10: ='Solar Power Plant Data'!H9/MAX('Solar Power Plant Data'!E9,0.0001) -> 0
A11: =HOUR('Solar Power Plant Data'!A10) -> 8 | B11: =DAY('Solar Power Plant Data'!A10) -> 1 | C11: =MONTH('Solar Power Plant Data'!A10) -> 1 | D11: =TEXT('Solar Power Plant Data'!A10,"ddd") -> Sun | E11: =IF(OR(D11="Sat",D11="Sun"),1,0) -> 1 | F11: {=IF(ROW()<25,"",INDEX('Solar Power Plant Data'!H:H,ROW()-1))} | G11: =IF(ROW()<25,"",AVERAGE(OFFSET('Solar Power Plant Data'!H33,-23,0,24,1))) | H11: ='Solar Power Plant Data'!H10/MAX('Solar Power Plant Data'!E10,0.0001) -> 0
A12: =HOUR('Solar Power Plant Data'!A11) -> 9 | B12: =DAY('Solar Power Plant Data'!A11) -> 1 | C12: =MONTH('Solar Power Plant Data'!A11) -> 1 | D12: =TEXT('Solar Power Plant Data'!A11,"ddd") -> Sun | E12: =IF(OR(D12="Sat",D12="Sun"),1,0) -> 1 | F12: {=IF(ROW()<25,"",INDEX('Solar Power Plant Data'!H:H,ROW()-1))} | G12: =IF(ROW()<25,"",AVERAGE(OFFSET('Solar Power Plant Data'!H34,-23,0,24,1))) | H12: ='Solar Power Plant Data'!H11/MAX('Solar Power Plant Data'!E11,0.0001) -> 0
A13: =HOUR('Solar Power Plant Data'!A12) -> 10 | B13: =DAY('Solar Power Plant Data'!A12) -> 1 | C13: =MONTH('Solar Power Plant Data'!A12) -> 1 | D13: =TEXT('Solar Power Plant Data'!A12,"ddd") -> Sun | E13: =IF(OR(D13="Sat",D13="Sun"),1,0) -> 1 | F13: {=IF(ROW()<25,"",INDEX('Solar Power Plant Data'!H:H,ROW()-1))} | G13: =IF(ROW()<25,"",AVERAGE(OFFSET('Solar Power Plant Data'!H35,-23,0,24,1))) | H13: ='Solar Power Plant Data'!H12/MAX('Solar Power Plant Data'!E12,0.0001) -> 0
A14: =HOUR('Solar Power Plant Data'!A13) -> 11 | B14: =DAY('Solar Power Plant Data'!A13) -> 1 | C14: =MONTH('Solar Power Plant Data'!A13) -> 1 | D14: =TEXT('Solar Power Plant Data'!A13,"ddd") -> Sun | E14: =IF(OR(D14="Sat",D14="Sun"),1,0) -> 1 | F14: {=IF(ROW()<25,"",INDEX('Solar Power Plant Data'!H:H,ROW()-1))} | G14: =IF(ROW()<25,"",AVERAGE(OFFSET('Solar Power Plant Data'!H36,-23,0,24,1))) | H14: ='Solar Power Plant Data'!H13/MAX('Solar Power Plant Data'!E13,0.0001) -> 21583330000
... A746: =HOUR('Solar Power Plant Data'!A745) -> 2 | B746: =DAY('Solar Power Plant Data'!A745) -> 11 | C746: =MONTH('Solar Power Plant Data'!A745) -> 4 | D746: =TEXT('Solar Power Plant Data'!A745,"ddd") -> Wed | E746: =IF(OR(D746="Sat",D746="Sun"),1,0) -> 0 | F746: {=IF(ROW()<25,"",INDEX('Solar Power Plant Data'!H:H,ROW()-1))} -> 0 | G746: =IF(ROW()<25,"",AVERAGE(OFFSET('Solar Power Plant Data'!H768,-23,0,24,1))) -> 0 | H746: ='Solar Power Plant Data'!H745/MAX('Solar Power Plant Data'!E745,0.0001) -> 0

Sheet Forecasting
A1: Datetime | B1: Actual_Production | C1: Forecast_Persistence | D1: Error | E1: ABS_Error | F1: Error^2
A2: ='Solar Power Plant Data'!A2 -> 42736 | B2: ='Solar Power Plant Data'!H2 -> 0 | C2: =IF(ROW()<25,"",INDEX(B:B,ROW()-24)) | D2: =B2-C2 -> 0 | E2: =ABS(D2) -> 0 | F2: =(D2)^2 -> 0
A3: ='Solar Power Plant Data'!A3 -> 42736.042 | B3: ='Solar Power Plant Data'!H3 -> 0 | C3: =IF(ROW()<25,"",INDEX(B:B,ROW()-24)) | D3: =B3-C3 -> 0 | E3: =ABS(D3) -> 0 | F3: =(D3)^2 -> 0
A4: ='Solar Power Plant Data'!A4 -> 42736.083 | B4: ='Solar Power Plant Data'!H4 -> 0 | C4: =IF(ROW()<25,"",INDEX(B:B,ROW()-24)) | D4: =B4-C4 -> 0 | E4: =ABS(D4) -> 0 | F4: =(D4)^2 -> 0
A5: ='Solar Power Plant Data'!A5 -> 42736.125 | B5: ='Solar Power Plant Data'!H5 -> 0 | C5: =IF(ROW()<25,"",INDEX(B:B,ROW()-24)) | D5: =B5-C5 -> 0 | E5: =ABS(D5) -> 0 | F5: =(D5)^2 -> 0
A6: ='Solar Power Plant Data'!A6 -> 42736.167 | B6: ='Solar Power Plant Data'!H6 -> 0 | C6: =IF(ROW()<25,"",INDEX(B:B,ROW()-24)) | D6: =B6-C6 -> 0 | E6: =ABS(D6) -> 0 | F6: =(D6)^2 -> 0
A7: ='Solar Power Plant Data'!A7 -> 42736.208 | B7: ='Solar Power Plant Data'!H7 -> 0 | C7: =IF(ROW()<25,"",INDEX(B:B,ROW()-24)) | D7: =B7-C7 -> 0 | E7: =ABS(D7) -> 0 | F7: =(D7)^2 -> 0
A8: ='Solar Power Plant Data'!A8 -> 42736.25 | B8: ='Solar Power Plant Data'!H8 -> 0 | C8: =IF(ROW()<25,"",INDEX(B:B,ROW()-24)) | D8: =B8-C8 -> 0 | E8: =ABS(D8) -> 0 | F8: =(D8)^2 -> 0
A9: ='Solar Power Plant Data'!A9 -> 42736.292 | B9: ='Solar Power Plant Data'!H9 -> 0 | C9: =IF(ROW()<25,"",INDEX(B:B,ROW()-24)) | D9: =B9-C9 -> 0 | E9: =ABS(D9) -> 0 | F9: =(D9)^2 -> 0
A10: ='Solar Power Plant Data'!A10 -> 42736.333 | B10: ='Solar Power Plant Data'!H10 -> 0 | C10: =IF(ROW()<25,"",INDEX(B:B,ROW()-24)) | D10: =B10-C10 -> 0 | E10: =ABS(D10) -> 0 | F10: =(D10)^2 -> 0
A11: ='Solar Power Plant Data'!A11 -> 42736.375 | B11: ='Solar Power Plant Data'!H11 -> 0 | C11: =IF(ROW()<25,"",INDEX(B:B,ROW()-24)) | D11: =B11-C11 -> 0 | E11: =ABS(D11) -> 0 | F11: =(D11)^2 -> 0
A12: ='Solar Power Plant Data'!A12 -> 42736.417 | B12: ='Solar Power Plant Data'!H12 -> 0 | C12: =IF(ROW()<25,"",INDEX(B:B,ROW()-24)) | D12: =B12-C12 -> 0 | E12: =ABS(D12) -> 0 | F12: =(D12)^2 -> 0
A13: ='Solar Power Plant Data'!A13 -> 42736.458 | B13: ='Solar Power Plant Data'!H13 -> 2158333 | C13: =IF(ROW()<25,"",INDEX(B:B,ROW()-24)) | D13: =B13-C13 -> 2158333 | E13: =ABS(D13) -> 2158333 | F13: =(D13)^2 -> 4658401338889
... A745: ='Solar Power Plant Data'!A745 -> 43201.083 | B745: ='Solar Power Plant Data'!H745 -> 0 | C745: =IF(ROW()<25,"",INDEX(B:B,ROW()-24)) -> 0 | D745: =B745-C745 -> 0 | E745: =ABS(D745) -> 0 | F745: =(D745)^2 -> 0
A746: ='Solar Power Plant Data'!A746
A747: ='Solar Power Plant Data'!A747
A748: ='Solar Power Plant Data'!A748
A749: ='Solar Power Plant Data'!A749
A750: ='Solar Power Plant Data'!A750
A751: ='Solar Power Plant Data'!A751
A752: ='Solar Power Plant Data'!A752
A753: ='Solar Power Plant Data'!A753
